Workbook

Sheet 📋 Tracker
E1: 7TH – 14TH SEPTEMBER | G1: 15TH – 22TH SEPTEMBER | I1: 25TH SEPT- 1ST OCTOBER | K1: 2ND- 6TH OCTOBER | M1: 7TH- 11TH OCTOBER | O1: 12TH- 25TH OCTOBER
B2: CFA LEVEL 1 – 2027 CURRICULUM TRACKER (102 Learning Modules) | E2: Revision | F2: Questions | G2: Revision | H2: Questions | I2: Revision | J2: Questions | K2: Revision | L2: Questions | M2: Revision | N2: Questions | O2: Revision | P2: Questions
B3: Type 1 in the Status column to mark a module done → it turns ✅ automatically
B4: LM # | C4: Reading Name | D4: Status | E4: Status | F4: Status | G4: Status | H4: Status | I4: Status | J4: Status | K4: Status | L4: Status | M4: Status | N4: Status | O4: Status | P4: Status
B5: QUANTITATIVE METHODS
B6: 1 | C6: Returns of Financial Assets and Instruments | D6: 1 | E6: 1
B7: 2 | C7: Types of Financial Returns | D7: 1 | E7: 1
B8: 3 | C8: Benchmarking Returns | D8: 1 | E8: 1
B9: 4 | C9: The Time Value of Money in Finance | D9: 1 | E9: 1
B10: 5 | C10: Statistical Characteristics of Asset Returns | D10: 1 | E10: 1
B11: 6 | C11: Statistical Distributions for Financial Asset Prices and Returns | D11: 1 | E11: 1
B12: 7 | C12: Estimation and Hypothesis Testing | D12: 1 | E12: 1
B13: 8 | C13: The Return and Risk of a Financial Portfolio | D13: 1 | E13: 1
B14: 9 | C14: Simulation of Financial Asset Prices and Returns | D14: 1 | E14: 1
B15: 10 | C15: Applications of Simple Linear Regression in Finance | D15: 1 | E15: 1
B16: 11 | C16: Introduction to Financial Data Science | D16: 1 | E16: 1
B17: ECONOMICS
B18: 12 | C18: The Firm & Market Structures | D18: 1 | G18: 1
B19: 13 | C19: Understanding Business Cycles | D19: 1 | G19: 1
B20: 14 | C20: Fiscal Policy | D20: 1 | G20: 1
B21: 15 | C21: Monetary Policy | D21: 1 | G21: 1
B22: 16 | C22: Introduction to Geopolitics | D22: 1 | G22: 1
B23: 17 | C23: International Trade | D23: 1 | G23: 1
B24: 18 | C24: Capital Flows and the FX Market | D24: 1 | G24: 1
B25: 19 | C25: Exchange Rate Calculations | D25: 1 | G25: 1
B26: CORPORATE FINANCE
B27: 20 | C27: Organizational Forms, Corporate Issuer Features, and Ownership | D27: 1 | E27: 1
B28: 21 | C28: Investors and Other Stakeholders | D28: 1 | E28: 1
B29: 22 | C29: Corporate Governance: Conflicts, Mechanisms, Risks, and Benefits | D29: 1 | E29: 1
B30: 23 | C30: Working Capital and Liquidity | D30: 1 | E30: 1
B31: 24 | C31: Capital Investments and Capital Allocation | D31: 1 | E31: 1
B32: 25 | C32: Capital Structure | D32: 1 | E32: 1
B33: 26 | C33: Business Models | D33: 1 | E33: 1
B34: FINANCIAL STATEMENT ANALYSIS
B35: 27 | C35: Introduction to Financial Statement Analysis | D35: 1 | I35: 1 | K35: 2
B36: 28 | C36: Analyzing Income Statements | D36: 1 | I36: 1 | K36: 2
B37: 29 | C37: Analyzing Balance Sheets | D37: 1 | I37: 2 | K37: 2
B38: 30 | C38: Analyzing Statements of Cash Flows I | D38: 1 | I38: 2 | K38: 2
B39: 31 | C39: Analyzing Statements of Cash Flows II | D39: 1 | I39: 2 | K39: 2
B40: 32 | C40: Analysis of Inventories | D40: 1 | I40: 2 | K40: 2
...

Sheet 📊 Dashboard
B1: CFA LEVEL 1 – PROGRESS BY TOPIC (2027)
B2: Go to the Tracker sheet → type 1 to mark done → this dashboard updates automatically
B3: Topic | C3: Total LMs | D3: Completed | E3: Progress
B4: Quantitative Methods | C4: 11 | D4: =COUNTIF('📋 Tracker'!D6:D16,1) -> 11 | E4: =D4/C4 -> 1
B5: Economics | C5: 8 | D5: =COUNTIF('📋 Tracker'!D18:D25,1) -> 8 | E5: =D5/C5 -> 1
B6: Corporate Finance | C6: 7 | D6: =COUNTIF('📋 Tracker'!D27:D33,1) -> 7 | E6: =D6/C6 -> 1
B7: Financial Statement Analysis | C7: 12 | D7: =COUNTIF('📋 Tracker'!D35:D46,1) -> 12 | E7: =D7/C7 -> 1
B8: Equities | C8: 12 | D8: =COUNTIF('📋 Tracker'!D48:D59,1) -> 12 | E8: =D8/C8 -> 1
B9: Fixed Income | C9: 19 | D9: =COUNTIF('📋 Tracker'!D61:D79,1) -> 19 | E9: =D9/C9 -> 1
B10: Derivatives | C10: 10 | D10: =COUNTIF('📋 Tracker'!D81:D90,1) -> 10 | E10: =D10/C10 -> 1
B11: Alternative Investments | C11: 7 | D11: =COUNTIF('📋 Tracker'!D92:D98,1) -> 7 | E11: =D11/C11 -> 1
B12: Portfolio Construction | C12: 6 | D12: =COUNTIF('📋 Tracker'!D100:D105,1) -> 6 | E12: =D12/C12 -> 1
B13: Ethics | C13: 10 | D13: =COUNTIF('📋 Tracker'!D107:D116,1) -> 10 | E13: =D13/C13 -> 1
B14: TOTAL | C14: 102 | D14: =SUM(D4:D13) -> 102 | E14: =D14/102 -> 1
B16: ="Overall: "&TEXT(D14/102,"0.0%")&" complete ("&D14&" / 102 LMs)" -> Overall: 100.0% complete (102 / 102 LMs)
B18: EXAM TOPIC WEIGHTS (CFA Level 1 – 2027)
B19: Topic | C19: Exam Weight | D19: Min % | E19: Max %
B20: Ethics | C20: 15–20% | D20: 0.15 | E20: 0.2
B21: Equities | C21: 11–14% | D21: 0.11 | E21: 0.14
B22: Financial Statement Analysis | C22: 11–14% | D22: 0.11 | E22: 0.14
B23: Fixed Income | C23: 11–14% | D23: 0.11 | E23: 0.14
B24: Quantitative Methods | C24: 11–14% | D24: 0.11 | E24: 0.14
B25: Portfolio Construction | C25: 8–12% | D25: 0.08 | E25: 0.12
B26: Alternative Investments | C26: 6–9% | D26: 0.06 | E26: 0.09
B27: Corporate Finance | C27: 6–9% | D27: 0.06 | E27: 0.09
B28: Economics | C28: 6–9% | D28: 0.06 | E28: 0.09
B29: Derivatives | C29: 6–9% | D29: 0.06 | E29: 0.09
B30: Source: CFA Institute 2027 Level I Exam Topic Area Weights
